<?xml version="1.0" ?>
<robot name="Robot">
  <!--Generated by CROSS, a ROS Workbench for FreeCAD (https://github.com/galou/freecad.cross)-->
  <link name="gripper_base_link">
    <visual>
      <!--gripper_body_base-->
      <origin rpy="0.0 -0.0 0.0" xyz="0.0 0.0 0.0"/>
      <geometry>
        <mesh filename="package://gripper/meshes/freecad_gripper_gripper_body_base.dae"/>
      </geometry>
    </visual>
    <collision>
      <!--gripper_body_base-->
      <origin rpy="0.0 -0.0 0.0" xyz="0.0 0.0 0.0"/>
      <geometry>
        <mesh filename="package://gripper/meshes/freecad_gripper_gripper_body_base.dae"/>
      </geometry>
    </collision>
    <inertial>
      <mass value="0.0"/>
      <origin rpy="0.0 -0.0 0.0" xyz="0.0 0.0 0.0"/>
      <inertia ixx="0.0" ixy="0.0" ixz="0.0" iyy="0.0" iyz="0.0" izz="0.0"/>
    </inertial>
  </link>
  <link name="finger_link">
    <visual>
      <!--finger-->
      <origin rpy="0.0 -0.0 0.0" xyz="0.0 0.0 0.0"/>
      <geometry>
        <mesh filename="package://gripper/meshes/freecad_gripper_finger.dae"/>
      </geometry>
    </visual>
    <collision>
      <!--finger-->
      <origin rpy="0.0 -0.0 0.0" xyz="0.0 0.0 0.0"/>
      <geometry>
        <mesh filename="package://gripper/meshes/freecad_gripper_finger.dae"/>
      </geometry>
    </collision>
    <inertial>
      <mass value="0.0"/>
      <origin rpy="0.0 -0.0 0.0" xyz="0.0 0.0 0.0"/>
      <inertia ixx="0.0" ixy="0.0" ixz="0.0" iyy="0.0" iyz="0.0" izz="0.0"/>
    </inertial>
  </link>
  <joint name="finger_joint" type="prismatic">
    <parent link="gripper_base_link"/>
    <child link="finger_link"/>
    <origin rpy="0.0 -0.0 0.0" xyz="0.08 0.0 0.067"/>
    <axis xyz="0 0 1"/>
    <limit effort="1000.0" lower="-0.079" upper="0.0" velocity="0.0"/>
  </joint>
</robot>
